2019-12-07 20:22:36,764 ERROR: Exception on /edit_profile [POST] [in /Users/williamkenrick/.pyenv/versions/3.8.0/lib/python3.8/site-packages/flask/app.py:1890]
Traceback (most recent call last):
  File "/Users/williamkenrick/.pyenv/versions/3.8.0/lib/python3.8/site-packages/sqlalchemy/engine/base.py", line 1245, in _execute_context
    self.dialect.do_execute(
  File "/Users/williamkenrick/.pyenv/versions/3.8.0/lib/python3.8/site-packages/sqlalchemy/engine/default.py", line 581, in do_execute
    cursor.execute(statement, parameters)
sqlite3.IntegrityError: UNIQUE constraint failed: user.username

The above exception was the direct cause of the following exception:

Traceback (most recent call last):
  File "/Users/williamkenrick/.pyenv/versions/3.8.0/lib/python3.8/site-packages/flask/app.py", line 2446, in wsgi_app
    response = self.full_dispatch_request()
  File "/Users/williamkenrick/.pyenv/versions/3.8.0/lib/python3.8/site-packages/flask/app.py", line 1951, in full_dispatch_request
    rv = self.handle_user_exception(e)
  File "/Users/williamkenrick/.pyenv/versions/3.8.0/lib/python3.8/site-packages/flask/app.py", line 1820, in handle_user_exception
    reraise(exc_type, exc_value, tb)
  File "/Users/williamkenrick/.pyenv/versions/3.8.0/lib/python3.8/site-packages/flask/_compat.py", line 39, in reraise
    raise value
  File "/Users/williamkenrick/.pyenv/versions/3.8.0/lib/python3.8/site-packages/flask/app.py", line 1949, in full_dispatch_request
    rv = self.dispatch_request()
  File "/Users/williamkenrick/.pyenv/versions/3.8.0/lib/python3.8/site-packages/flask/app.py", line 1935, in dispatch_request
    return self.view_functions[rule.endpoint](**req.view_args)
  File "/Users/williamkenrick/Projects/python/microblogx/app/routes.py", line 83, in edit_profile
    db.session.commit()
  File "/Users/williamkenrick/.pyenv/versions/3.8.0/lib/python3.8/site-packages/sqlalchemy/orm/scoping.py", line 162, in do
    return getattr(self.registry(), name)(*args, **kwargs)
  File "/Users/williamkenrick/.pyenv/versions/3.8.0/lib/python3.8/site-packages/sqlalchemy/orm/session.py", line 1027, in commit
    self.transaction.commit()
  File "/Users/williamkenrick/.pyenv/versions/3.8.0/lib/python3.8/site-packages/sqlalchemy/orm/session.py", line 494, in commit
    self._prepare_impl()
  File "/Users/williamkenrick/.pyenv/versions/3.8.0/lib/python3.8/site-packages/sqlalchemy/orm/session.py", line 473, in _prepare_impl
    self.session.flush()
  File "/Users/williamkenrick/.pyenv/versions/3.8.0/lib/python3.8/site-packages/sqlalchemy/orm/session.py", line 2470, in flush
    self._flush(objects)
  File "/Users/williamkenrick/.pyenv/versions/3.8.0/lib/python3.8/site-packages/sqlalchemy/orm/session.py", line 2608, in _flush
    transaction.rollback(_capture_exception=True)
  File "/Users/williamkenrick/.pyenv/versions/3.8.0/lib/python3.8/site-packages/sqlalchemy/util/langhelpers.py", line 68, in __exit__
    compat.reraise(exc_type, exc_value, exc_tb)
  File "/Users/williamkenrick/.pyenv/versions/3.8.0/lib/python3.8/site-packages/sqlalchemy/util/compat.py", line 153, in reraise
    raise value
  File "/Users/williamkenrick/.pyenv/versions/3.8.0/lib/python3.8/site-packages/sqlalchemy/orm/session.py", line 2568, in _flush
    flush_context.execute()
  File "/Users/williamkenrick/.pyenv/versions/3.8.0/lib/python3.8/site-packages/sqlalchemy/orm/unitofwork.py", line 422, in execute
    rec.execute(self)
  File "/Users/williamkenrick/.pyenv/versions/3.8.0/lib/python3.8/site-packages/sqlalchemy/orm/unitofwork.py", line 586, in execute
    persistence.save_obj(
  File "/Users/williamkenrick/.pyenv/versions/3.8.0/lib/python3.8/site-packages/sqlalchemy/orm/persistence.py", line 230, in save_obj
    _emit_update_statements(
  File "/Users/williamkenrick/.pyenv/versions/3.8.0/lib/python3.8/site-packages/sqlalchemy/orm/persistence.py", line 995, in _emit_update_statements
    c = cached_connections[connection].execute(
  File "/Users/williamkenrick/.pyenv/versions/3.8.0/lib/python3.8/site-packages/sqlalchemy/engine/base.py", line 982, in execute
    return meth(self, multiparams, params)
  File "/Users/williamkenrick/.pyenv/versions/3.8.0/lib/python3.8/site-packages/sqlalchemy/sql/elements.py", line 287, in _execute_on_connection
    return connection._execute_clauseelement(self, multiparams, params)
  File "/Users/williamkenrick/.pyenv/versions/3.8.0/lib/python3.8/site-packages/sqlalchemy/engine/base.py", line 1095, in _execute_clauseelement
    ret = self._execute_context(
  File "/Users/williamkenrick/.pyenv/versions/3.8.0/lib/python3.8/site-packages/sqlalchemy/engine/base.py", line 1249, in _execute_context
    self._handle_dbapi_exception(
  File "/Users/williamkenrick/.pyenv/versions/3.8.0/lib/python3.8/site-packages/sqlalchemy/engine/base.py", line 1476, in _handle_dbapi_exception
    util.raise_from_cause(sqlalchemy_exception, exc_info)
  File "/Users/williamkenrick/.pyenv/versions/3.8.0/lib/python3.8/site-packages/sqlalchemy/util/compat.py", line 398, in raise_from_cause
    reraise(type(exception), exception, tb=exc_tb, cause=cause)
  File "/Users/williamkenrick/.pyenv/versions/3.8.0/lib/python3.8/site-packages/sqlalchemy/util/compat.py", line 152, in reraise
    raise value.with_traceback(tb)
  File "/Users/williamkenrick/.pyenv/versions/3.8.0/lib/python3.8/site-packages/sqlalchemy/engine/base.py", line 1245, in _execute_context
    self.dialect.do_execute(
  File "/Users/williamkenrick/.pyenv/versions/3.8.0/lib/python3.8/site-packages/sqlalchemy/engine/default.py", line 581, in do_execute
    cursor.execute(statement, parameters)
sqlalchemy.exc.IntegrityError: (sqlite3.IntegrityError) UNIQUE constraint failed: user.username
[SQL: UPDATE user SET username=?, about_me=? WHERE user.id = ?]
[parameters: ('pkenrick', 'My info goes here....', 8)]
(Background on this error at: http://sqlalche.me/e/gkpj)
2019-12-08 07:46:13,516 ERROR: Exception on /edit_profile [POST] [in /Users/williamkenrick/.pyenv/versions/3.8.0/lib/python3.8/site-packages/flask/app.py:1890]
Traceback (most recent call last):
  File "/Users/williamkenrick/.pyenv/versions/3.8.0/lib/python3.8/site-packages/flask/app.py", line 2446, in wsgi_app
    response = self.full_dispatch_request()
  File "/Users/williamkenrick/.pyenv/versions/3.8.0/lib/python3.8/site-packages/flask/app.py", line 1951, in full_dispatch_request
    rv = self.handle_user_exception(e)
  File "/Users/williamkenrick/.pyenv/versions/3.8.0/lib/python3.8/site-packages/flask/app.py", line 1820, in handle_user_exception
    reraise(exc_type, exc_value, tb)
  File "/Users/williamkenrick/.pyenv/versions/3.8.0/lib/python3.8/site-packages/flask/_compat.py", line 39, in reraise
    raise value
  File "/Users/williamkenrick/.pyenv/versions/3.8.0/lib/python3.8/site-packages/flask/app.py", line 1949, in full_dispatch_request
    rv = self.dispatch_request()
  File "/Users/williamkenrick/.pyenv/versions/3.8.0/lib/python3.8/site-packages/flask/app.py", line 1935, in dispatch_request
    return self.view_functions[rule.endpoint](**req.view_args)
  File "/Users/williamkenrick/Projects/python/microblogx/app/routes.py", line 80, in edit_profile
    if form.validate_on_submit():
  File "/Users/williamkenrick/.pyenv/versions/3.8.0/lib/python3.8/site-packages/flask_wtf/form.py", line 101, in validate_on_submit
    return self.is_submitted() and self.validate()
  File "/Users/williamkenrick/.pyenv/versions/3.8.0/lib/python3.8/site-packages/wtforms/form.py", line 310, in validate
    return super(Form, self).validate(extra)
  File "/Users/williamkenrick/.pyenv/versions/3.8.0/lib/python3.8/site-packages/wtforms/form.py", line 152, in validate
    if not field.validate(self, extra):
  File "/Users/williamkenrick/.pyenv/versions/3.8.0/lib/python3.8/site-packages/wtforms/fields/core.py", line 206, in validate
    stop_validation = self._run_validation_chain(form, chain)
  File "/Users/williamkenrick/.pyenv/versions/3.8.0/lib/python3.8/site-packages/wtforms/fields/core.py", line 226, in _run_validation_chain
    validator(form, self)
  File "/Users/williamkenrick/Projects/python/microblogx/app/forms.py", line 35, in validate_username
    if username != current_user.username:
NameError: name 'current_user' is not defined
2019-12-08 08:20:50,475 ERROR: Exception on /edit_profile [GET] [in /Users/williamkenrick/.pyenv/versions/3.8.0/lib/python3.8/site-packages/flask/app.py:1890]
Traceback (most recent call last):
  File "/Users/williamkenrick/.pyenv/versions/3.8.0/lib/python3.8/site-packages/flask/app.py", line 2446, in wsgi_app
    response = self.full_dispatch_request()
  File "/Users/williamkenrick/.pyenv/versions/3.8.0/lib/python3.8/site-packages/flask/app.py", line 1951, in full_dispatch_request
    rv = self.handle_user_exception(e)
  File "/Users/williamkenrick/.pyenv/versions/3.8.0/lib/python3.8/site-packages/flask/app.py", line 1820, in handle_user_exception
    reraise(exc_type, exc_value, tb)
  File "/Users/williamkenrick/.pyenv/versions/3.8.0/lib/python3.8/site-packages/flask/_compat.py", line 39, in reraise
    raise value
  File "/Users/williamkenrick/.pyenv/versions/3.8.0/lib/python3.8/site-packages/flask/app.py", line 1949, in full_dispatch_request
    rv = self.dispatch_request()
  File "/Users/williamkenrick/.pyenv/versions/3.8.0/lib/python3.8/site-packages/flask/app.py", line 1935, in dispatch_request
    return self.view_functions[rule.endpoint](**req.view_args)
  File "/Users/williamkenrick/Projects/python/microblogx/app/routes.py", line 78, in edit_profile
    form = EditUserForm(current_user.username)
  File "/Users/williamkenrick/.pyenv/versions/3.8.0/lib/python3.8/site-packages/wtforms/form.py", line 212, in __call__
    return type.__call__(cls, *args, **kwargs)
  File "/Users/williamkenrick/Projects/python/microblogx/app/forms.py", line 35, in __init__
    super(EditUserForm, self).__init__(*args, **kwargs)
NameError: name 'args' is not defined
